<?xml version="1.0" encoding="utf-8"?>
<!-- This URDF was automatically created by SolidWorks to URDF Exporter! Originally created by Stephen Brawner (brawner@gmail.com) 
     Commit Version: 1.6.0-4-g7f85cfe  Build Version: 1.6.7995.38578
     For more information, please see http://wiki.ros.org/sw_urdf_exporter -->
<robot
  name="tracked_vehicle01">
  <link
    name="base_link">
    <inertial>
      <origin
        xyz="-0.40719 1.118 1.6289"
        rpy="0 0 0" />
      <mass
        value="71.541" />
      <inertia
        ixx="1.3082"
        ixy="0.025336"
        ixz="0.006337"
        iyy="4.167"
        iyz="0.0003898"
        izz="3.5463" />
    </inertial>
    <visual>
      <origin
        xyz="0 0 0"
        rpy="0 0 0" />
      <geometry>
        <mesh
          filename="package://tracked_vehicle01/meshes/base_link.STL" />
      </geometry>
      <material
        name="">
        <color
          rgba="1 1 1 1" />
      </material>
    </visual>
    <collision>
      <origin
        xyz="0 0 0"
        rpy="0 0 0" />
      <geometry>
        <mesh
          filename="package://tracked_vehicle01/meshes/base_link.STL" />
      </geometry>
    </collision>
  </link>
  <link
    name="wheel1_Link">
    <inertial>
      <origin
        xyz="1.249E-08 -0.031581 7.4203E-05"
        rpy="0 0 0" />
      <mass
        value="0.78706" />
      <inertia
        ixx="0.0021017"
        ixy="-3.9045E-10"
        ixz="1.0314E-10"
        iyy="0.0034145"
        iyz="-1.9413E-06"
        izz="0.0021023" />
    </inertial>
    <visual>
      <origin
        xyz="0 0 0"
        rpy="0 0 0" />
      <geometry>
        <mesh
          filename="package://tracked_vehicle01/meshes/wheel1_Link.STL" />
      </geometry>
      <material
        name="">
        <color
          rgba="0.81176 0.58431 0 1" />
      </material>
    </visual>
    <collision>
      <origin
        xyz="0 0 0"
        rpy="0 0 0" />
      <geometry>
        <mesh
          filename="package://tracked_vehicle01/meshes/wheel1_Link.STL" />
      </geometry>
    </collision>
  </link>
  <joint
    name="wheel1_joint"
    type="continuous">
    <origin
      xyz="0.17257 -1.9927 0.96109"
      rpy="0 0 3.1416" />
    <parent
      link="base_link" />
    <child
      link="wheel1_Link" />
    <axis
      xyz="0 1 0" />
  </joint>
  <link
    name="wheel2_Link">
    <inertial>
      <origin
        xyz="5.3291E-15 -0.075 1.9984E-15"
        rpy="0 0 0" />
      <mass
        value="1.1022" />
      <inertia
        ixx="0.004462"
        ixy="-6.497E-19"
        ixz="-3.9223E-19"
        iyy="0.0031755"
        iyz="-1.0855E-18"
        izz="0.004462" />
    </inertial>
    <visual>
      <origin
        xyz="0 0 0"
        rpy="0 0 0" />
      <geometry>
        <mesh
          filename="package://tracked_vehicle01/meshes/wheel2_Link.STL" />
      </geometry>
      <material
        name="">
        <color
          rgba="0.81176 0.21569 0 1" />
      </material>
    </visual>
    <collision>
      <origin
        xyz="0 0 0"
        rpy="0 0 0" />
      <geometry>
        <mesh
          filename="package://tracked_vehicle01/meshes/wheel2_Link.STL" />
      </geometry>
    </collision>
  </link>
  <joint
    name="wheel2_joint"
    type="continuous">
    <origin
      xyz="-0.11742 -2.0517 0.89905"
      rpy="0 0 3.1416" />
    <parent
      link="base_link" />
    <child
      link="wheel2_Link" />
    <axis
      xyz="0 1 0" />
  </joint>
  <link
    name="wheel3_Link">
    <inertial>
      <origin
        xyz="1.632E-14 -0.075 2.4425E-15"
        rpy="0 0 0" />
      <mass
        value="1.1022" />
      <inertia
        ixx="0.004462"
        ixy="2.1618E-18"
        ixz="-1.236E-18"
        iyy="0.0031755"
        iyz="8.0046E-19"
        izz="0.004462" />
    </inertial>
    <visual>
      <origin
        xyz="0 0 0"
        rpy="0 0 0" />
      <geometry>
        <mesh
          filename="package://tracked_vehicle01/meshes/wheel3_Link.STL" />
      </geometry>
      <material
        name="">
        <color
          rgba="0.81176 0.21569 0 1" />
      </material>
    </visual>
    <collision>
      <origin
        xyz="0 0 0"
        rpy="0 0 0" />
      <geometry>
        <mesh
          filename="package://tracked_vehicle01/meshes/wheel3_Link.STL" />
      </geometry>
    </collision>
  </link>
  <joint
    name="wheel3_joint"
    type="continuous">
    <origin
      xyz="-0.37742 -2.0517 0.899"
      rpy="0 0 3.1416" />
    <parent
      link="base_link" />
    <child
      link="wheel3_Link" />
    <axis
      xyz="0 1 0" />
  </joint>
  <link
    name="wheel4_Link">
    <inertial>
      <origin
        xyz="-5.218E-15 -0.075 2.4425E-15"
        rpy="0 0 0" />
      <mass
        value="1.1022" />
      <inertia
        ixx="0.004462"
        ixy="2.2277E-18"
        ixz="-5.7819E-19"
        iyy="0.0031755"
        iyz="-1.0322E-18"
        izz="0.004462" />
    </inertial>
    <visual>
      <origin
        xyz="0 0 0"
        rpy="0 0 0" />
      <geometry>
        <mesh
          filename="package://tracked_vehicle01/meshes/wheel4_Link.STL" />
      </geometry>
      <material
        name="">
        <color
          rgba="0.81176 0.21569 0 1" />
      </material>
    </visual>
    <collision>
      <origin
        xyz="0 0 0"
        rpy="0 0 0" />
      <geometry>
        <mesh
          filename="package://tracked_vehicle01/meshes/wheel4_Link.STL" />
      </geometry>
    </collision>
  </link>
  <joint
    name="wheel4_joint"
    type="continuous">
    <origin
      xyz="-0.63742 -2.0517 0.89896"
      rpy="0 0 3.1416" />
    <parent
      link="base_link" />
    <child
      link="wheel4_Link" />
    <axis
      xyz="0 1 0" />
  </joint>
  <link
    name="wheel5_Link">
    <inertial>
      <origin
        xyz="7.9936E-15 -0.019999 -4.885E-15"
        rpy="0 0 0" />
      <mass
        value="0.33834" />
      <inertia
        ixx="0.00052483"
        ixy="2.377E-20"
        ixz="4.9632E-19"
        iyy="0.0009698"
        iyz="2.4922E-21"
        izz="0.00052483" />
    </inertial>
    <visual>
      <origin
        xyz="0 0 0"
        rpy="0 0 0" />
      <geometry>
        <mesh
          filename="package://tracked_vehicle01/meshes/wheel5_Link.STL" />
      </geometry>
      <material
        name="">
        <color
          rgba="0.81176 0.58431 0 1" />
      </material>
    </visual>
    <collision>
      <origin
        xyz="0 0 0"
        rpy="0 0 0" />
      <geometry>
        <mesh
          filename="package://tracked_vehicle01/meshes/wheel5_Link.STL" />
      </geometry>
    </collision>
  </link>
  <joint
    name="wheel5_jointk"
    type="continuous">
    <origin
      xyz="-0.86837 -1.9967 0.98593"
      rpy="0 0 3.1416" />
    <parent
      link="base_link" />
    <child
      link="wheel5_Link" />
    <axis
      xyz="0 1 0" />
  </joint>
  <link
    name="wheel6_Link">
    <inertial>
      <origin
        xyz="4.6629E-15 0.019999 1.2212E-15"
        rpy="0 0 0" />
      <mass
        value="0.33834" />
      <inertia
        ixx="0.00052483"
        ixy="1.2629E-19"
        ixz="3.8129E-19"
        iyy="0.0009698"
        iyz="-5.7781E-19"
        izz="0.00052483" />
    </inertial>
    <visual>
      <origin
        xyz="0 0 0"
        rpy="0 0 0" />
      <geometry>
        <mesh
          filename="package://tracked_vehicle01/meshes/wheel6_Link.STL" />
      </geometry>
      <material
        name="">
        <color
          rgba="0.81176 0.58431 0 1" />
      </material>
    </visual>
    <collision>
      <origin
        xyz="0 0 0"
        rpy="0 0 0" />
      <geometry>
        <mesh
          filename="package://tracked_vehicle01/meshes/wheel6_Link.STL" />
      </geometry>
    </collision>
  </link>
  <joint
    name="wheel6_joint"
    type="continuous">
    <origin
      xyz="-0.86837 -1.2567 0.98593"
      rpy="0 0 3.1416" />
    <parent
      link="base_link" />
    <child
      link="wheel6_Link" />
    <axis
      xyz="0 1 0" />
  </joint>
  <link
    name="wheel7_Link">
    <inertial>
      <origin
        xyz="1.2657E-14 0.075 2.3315E-15"
        rpy="0 0 0" />
      <mass
        value="1.1022" />
      <inertia
        ixx="0.004462"
        ixy="2.117E-18"
        ixz="1.2679E-19"
        iyy="0.0031755"
        iyz="-6.2841E-19"
        izz="0.004462" />
    </inertial>
    <visual>
      <origin
        xyz="0 0 0"
        rpy="0 0 0" />
      <geometry>
        <mesh
          filename="package://tracked_vehicle01/meshes/wheel7_Link.STL" />
      </geometry>
      <material
        name="">
        <color
          rgba="0.81176 0.21569 0 1" />
      </material>
    </visual>
    <collision>
      <origin
        xyz="0 0 0"
        rpy="0 0 0" />
      <geometry>
        <mesh
          filename="package://tracked_vehicle01/meshes/wheel7_Link.STL" />
      </geometry>
    </collision>
  </link>
  <joint
    name="wheel7_joint"
    type="continuous">
    <origin
      xyz="-0.63742 -1.2017 0.89896"
      rpy="0 0 3.1416" />
    <parent
      link="base_link" />
    <child
      link="wheel7_Link" />
    <axis
      xyz="0 -1 0" />
  </joint>
  <link
    name="wheel8_Link">
    <inertial>
      <origin
        xyz="-1.5543E-15 0.075 2.1094E-15"
        rpy="0 0 0" />
      <mass
        value="1.1022" />
      <inertia
        ixx="0.004462"
        ixy="-1.2067E-18"
        ixz="-2.1126E-19"
        iyy="0.0031755"
        iyz="-1.0203E-19"
        izz="0.004462" />
    </inertial>
    <visual>
      <origin
        xyz="0 0 0"
        rpy="0 0 0" />
      <geometry>
        <mesh
          filename="package://tracked_vehicle01/meshes/wheel8_Link.STL" />
      </geometry>
      <material
        name="">
        <color
          rgba="0.81176 0.21569 0 1" />
      </material>
    </visual>
    <collision>
      <origin
        xyz="0 0 0"
        rpy="0 0 0" />
      <geometry>
        <mesh
          filename="package://tracked_vehicle01/meshes/wheel8_Link.STL" />
      </geometry>
    </collision>
  </link>
  <joint
    name="wheel8_joint"
    type="continuous">
    <origin
      xyz="-0.37742 -1.2017 0.899"
      rpy="0 0 3.1416" />
    <parent
      link="base_link" />
    <child
      link="wheel8_Link" />
    <axis
      xyz="0 -1 0" />
  </joint>
  <link
    name="wheel9_Link">
    <inertial>
      <origin
        xyz="1.0381E-08 0.075 6.5657E-05"
        rpy="0 0 0" />
      <mass
        value="1.1155" />
      <inertia
        ixx="0.0044652"
        ixy="-3.4527E-19"
        ixz="2.0986E-10"
        iyy="0.0031779"
        iyz="1.7866E-18"
        izz="0.0044665" />
    </inertial>
    <visual>
      <origin
        xyz="0 0 0"
        rpy="0 0 0" />
      <geometry>
        <mesh
          filename="package://tracked_vehicle01/meshes/wheel9_Link.STL" />
      </geometry>
      <material
        name="">
        <color
          rgba="0.18039 0.18039 0.18039 1" />
      </material>
    </visual>
    <collision>
      <origin
        xyz="0 0 0"
        rpy="0 0 0" />
      <geometry>
        <mesh
          filename="package://tracked_vehicle01/meshes/wheel9_Link.STL" />
      </geometry>
    </collision>
  </link>
  <joint
    name="wheel9_joint"
    type="continuous">
    <origin
      xyz="-0.11742 -1.2017 0.89905"
      rpy="0 0 3.1416" />
    <parent
      link="base_link" />
    <child
      link="wheel9_Link" />
    <axis
      xyz="0 -1 0" />
  </joint>
  <link
    name="wheel10_Link">
    <inertial>
      <origin
        xyz="7.4203E-05 0.031581 -1.0974E-08"
        rpy="0 0 0" />
      <mass
        value="0.78706" />
      <inertia
        ixx="0.0021023"
        ixy="1.9413E-06"
        ixz="-8.0629E-11"
        iyy="0.0034145"
        iyz="-2.2342E-10"
        izz="0.0021017" />
    </inertial>
    <visual>
      <origin
        xyz="0 0 0"
        rpy="0 0 0" />
      <geometry>
        <mesh
          filename="package://tracked_vehicle01/meshes/wheel10_Link.STL" />
      </geometry>
      <material
        name="">
        <color
          rgba="0.81176 0.58431 0 1" />
      </material>
    </visual>
    <collision>
      <origin
        xyz="0 0 0"
        rpy="0 0 0" />
      <geometry>
        <mesh
          filename="package://tracked_vehicle01/meshes/wheel10_Link.STL" />
      </geometry>
    </collision>
  </link>
  <joint
    name="wheel510_joint"
    type="continuous">
    <origin
      xyz="0.17257 -1.2607 0.96109"
      rpy="0 0 3.1416" />
    <parent
      link="base_link" />
    <child
      link="wheel10_Link" />
    <axis
      xyz="0 -1 0" />
  </joint>
  <link
    name="radar_Link">
    <inertial>
      <origin
        xyz="2.7756E-16 2.2204E-16 0.076677"
        rpy="0 0 0" />
      <mass
        value="3.6018" />
      <inertia
        ixx="0.013262"
        ixy="-7.4934E-23"
        ixz="1.279E-18"
        iyy="0.013262"
        iyz="1.553E-18"
        izz="0.013876" />
    </inertial>
    <visual>
      <origin
        xyz="0 0 0"
        rpy="0 0 0" />
      <geometry>
        <mesh
          filename="package://tracked_vehicle01/meshes/radar_Link.STL" />
      </geometry>
      <material
        name="">
        <color
          rgba="1 1 1 1" />
      </material>
    </visual>
    <collision>
      <origin
        xyz="0 0 0"
        rpy="0 0 0" />
      <geometry>
        <mesh
          filename="package://tracked_vehicle01/meshes/radar_Link.STL" />
      </geometry>
    </collision>
  </link>
  <joint
    name="radar_joint"
    type="fixed">
    <origin
      xyz="-0.27001 -1.6367 1.472"
      rpy="0 0.00015811 -3.1416" />
    <parent
      link="base_link" />
    <child
      link="radar_Link" />
    <axis
      xyz="0 0 0" />
  </joint>
  <link
    name="GPS_Link">
    <inertial>
      <origin
        xyz="0.093645 -0.36299 0.3864"
        rpy="0 0 0" />
      <mass
        value="2.1661" />
      <inertia
        ixx="0.011976"
        ixy="-4.7061E-18"
        ixz="0.00081281"
        iyy="0.0094436"
        iyz="1.1245E-18"
        izz="0.017601" />
    </inertial>
    <visual>
      <origin
        xyz="0 0 0"
        rpy="0 0 0" />
      <geometry>
        <mesh
          filename="package://tracked_vehicle01/meshes/GPS_Link.STL" />
      </geometry>
      <material
        name="">
        <color
          rgba="1 1 1 1" />
      </material>
    </visual>
    <collision>
      <origin
        xyz="0 0 0"
        rpy="0 0 0" />
      <geometry>
        <mesh
          filename="package://tracked_vehicle01/meshes/GPS_Link.STL" />
      </geometry>
    </collision>
  </link>
  <joint
    name="GPS_joint"
    type="fixed">
    <origin
      xyz="0.17257 -1.9927 0.96109"
      rpy="0 0 3.1416" />
    <parent
      link="base_link" />
    <child
      link="GPS_Link" />
    <axis
      xyz="0 0 0" />
  </joint>
  <link
    name="imu_Link">
    <inertial>
      <origin
        xyz="-0.0054677 4.885E-15 -0.024999"
        rpy="0 0 0" />
      <mass
        value="2.07" />
      <inertia
        ixx="0.018699"
        ixy="-6.5343E-18"
        ixz="2.518E-06"
        iyy="0.017436"
        iyz="2.8627E-18"
        izz="0.034625" />
    </inertial>
    <visual>
      <origin
        xyz="0 0 0"
        rpy="0 0 0" />
      <geometry>
        <mesh
          filename="package://tracked_vehicle01/meshes/imu_Link.STL" />
      </geometry>
      <material
        name="">
        <color
          rgba="1 1 1 1" />
      </material>
    </visual>
    <collision>
      <origin
        xyz="0 0 0"
        rpy="0 0 0" />
      <geometry>
        <mesh
          filename="package://tracked_vehicle01/meshes/imu_Link.STL" />
      </geometry>
    </collision>
  </link>
  <joint
    name="imu_joint"
    type="fixed">
    <origin
      xyz="0.12318 -1.6297 1.3171"
      rpy="0 0 3.1416" />
    <parent
      link="base_link" />
    <child
      link="imu_Link" />
    <axis
      xyz="0 0 0" />
  </joint>
  <link
    name="control_Link">
    <inertial>
      <origin
        xyz="-0.0096163 5.3291E-15 -0.049998"
        rpy="0 0 0" />
      <mass
        value="3.984" />
      <inertia
        ixx="0.10849"
        ixy="-1.1744E-16"
        ixz="4.6873E-06"
        iyy="0.043019"
        iyz="-4.7954E-17"
        izz="0.13814" />
    </inertial>
    <visual>
      <origin
        xyz="0 0 0"
        rpy="0 0 0" />
      <geometry>
        <mesh
          filename="package://tracked_vehicle01/meshes/control_Link.STL" />
      </geometry>
      <material
        name="">
        <color
          rgba="1 1 1 1" />
      </material>
    </visual>
    <collision>
      <origin
        xyz="0 0 0"
        rpy="0 0 0" />
      <geometry>
        <mesh
          filename="package://tracked_vehicle01/meshes/control_Link.STL" />
      </geometry>
    </collision>
  </link>
  <joint
    name="control_joint"
    type="fixed">
    <origin
      xyz="0.12319 -1.6297 1.2671"
      rpy="0 0 3.1416" />
    <parent
      link="base_link" />
    <child
      link="control_Link" />
    <axis
      xyz="0 0 0" />
  </joint>
</robot>